Workbook

Sheet problemas
A2: Problema | B2: Decisão no filtro revisto | C2: Carimbo de data/hora | D2: Consentimento livre e esclarecido: Após ter sido esclarecido sobre a natureza da pesquisa, seus objetivos, métodos, benefícios previstos, potenciais riscos e o incômodo que esta possa acarretar, aceito participar do preenchimento do questionário, disponível no Google Forms. | E2: Nome completo do participante | F2: Você se comunica por LIBRAS, tem 18 anos ou mais e mora em alguma das cidades do mapa? | G2: Qual é o número do seu telefone celular com DDD? | H2: Qual é o seu e-mail? | I2: Qual é a sua data de nascimento? | J2: Qual é o seu sexo? | K2: Qual é a sua escolaridade? | L2: Você trabalha? | M2: Qual é a sua cor (ou raça)? | N2: Qual sua religião? | O2: Qual cidade você mora? | P2: Qual bairro você mora? | Q2: Qual número do seu CEP? | R2: Você tem diabetes? | S2: Você tem pressão alta? | T2: Qual é a sua opinião sobre sua saúde? | U2: Você fuma? | V2: Você toma bebidas alcoólicas? | W2: Você usa os serviços de saúde do SUS, por exemplo, centros de saúde, hospitais, exames e vários outros serviços de saúde? | X2: Quando você vai aos serviços de saúde do SUS como você avalia a comunicação com médicos, enfermeiros e diversos profissionais nestes serviços? | Y2: O intérprete da Central de Interpretação de Libras (CIL) vai no atendimento com você no serviço público de saúde SUS? | Z2: Você usa a rede particular de saúde? Exemplo: hospital, médico, convênio | AA2: Como você avalia a comunicação entre você e o profissional de saúde do convênio ou na rede particular, com médicos, enfermeiros e diversos outros profissionais, como é a comunicação? | AB2: Você usa aparelho auditivo? | AC2: Você conseguiu seu aparelho auditivo pelo SUS? | AD2: Como você avalia a comunicação entre você e o médico, a fonoaudióloga e os diversos outros profissionais do centro do SUS onde conseguiu o aparelho auditivo? | AE2: Você usa implante coclear? | AF2: Você conseguiu seu implante coclear pelo SUS? | AG2: Como você avalia a comunicação entre você e o médico, a fonoaudióloga e os diversos outros profissionais do centro do SUS onde conseguiu o implante coclear?
A3: Data de nascimento não preenchida | B3: =VLOOKUP(C3,filtro_revisto!$A$1:$B$262,2,0) -> TRUE | C3: 17/08/2021 23:35:59 | D3: Sim, aceito participar da pesquisa | E3: Luciana Aguera Rosa | F3: A - Sim | G3: 19993954343 | H3: luciana.aguerosa@gmail.com | J3: A - Feminino | K3: E - Pós-graduação (especialização, mestrado, doutorado) | L3: A - Sim, trabalho | M3: B - Branca | N3: D - Espírita | O3: Campinas | P3: Parque Brasília | Q3: 13091-464 | R3: C - Não tenho | S3: C - Não tenho | T3: B - Boa | U3: C - Não | V3: B - Sim, às vezes | W3: B - Não | Z3: A - Sim | AA3: B - Ruim, não sabem LIBRAS e preciso escrever português | AB3: B - Não | AE3: B - Não
A4: Nascimento em branco | B4: =VLOOKUP(C4,filtro_revisto!$A$1:$B$262,2,0) -> TRUE | C4: 18/08/2021 21:46:24 | D4: Sim, aceito participar da pesquisa | E4: Otávio Bortoluzo De Lorenzo | F4: A - Sim | H4: otavio.bortoluzo@gmail.com | J4: B - Masculino | K4: D - Superior (ou 3º grau) | L4: A - Sim, trabalho | M4: B - Branca | N4: D - Espírita | O4: Campinas | P4: Jardim Guanabara | R4: C - Não tenho | S4: C - Não tenho | T4: B - Boa | U4: C - Não | V4: B - Sim, às vezes | W4: A - Sim | X4: A - Ruim, não sabem LIBRAS e sou obrigado a oralizar | Y4: D - Não, porque não tem Central de Interpretação de Libras na minha cidade | Z4: A - Sim | AA4: A - Ruim, não sabem LIBRAS e sou obrigado a oralizar | AB4: A - Sim | AC4: A - Sim | AD4: A - Ruim, não sabe LIBRAS e sou obrigado a oralizar | AE4: B - Não
A5: Nascimento em branco | B5: =VLOOKUP(C5,filtro_revisto!$A$1:$B$262,2,0) -> TRUE | C5: 21/08/2021 12:28:37 | D5: Sim, aceito participar da pesquisa | E5: Augusto E.P.criscione | F5: A - Sim | H5: gucris4@gmail.com | J5: B - Masculino | K5: D - Superior (ou 3º grau) | L5: A - Sim, trabalho | M5: B - Branca | N5: C - Evangélica | O5: Campinas | P5: Parque eucaliptos | Q5: 13061 371 | R5: C - Não tenho | S5: C - Não tenho | T5: B - Boa | U5: C - Não | V5: C - Não | W5: B - Não | Z5: A - Sim | AA5: D - Boa, tem intérprete que me ajuda | AB5: A - Sim | AC5: B - Não | AE5: B - Não
A6: Nascimento em branco | B6: =VLOOKUP(C6,filtro_revisto!$A$1:$B$262,2,0) -> FALSE | C6: 26/08/2021 09:26:15
A7: Nascimento em branco | B7: =VLOOKUP(C7,filtro_revisto!$A$1:$B$262,2,0) -> FALSE | C7: 22/09/2021 16:55:45 | D7: Sim, aceito participar da pesquisa | E7: Antonia Carmen Martínez Magnusson | F7: B - Não | G7: 19992679599 | H7: bosquespal@gmail.com | J7: A - Feminino | K7: E - Pós-graduação (especialização, mestrado, doutorado) | L7: A - Sim, trabalho | M7: B - Branca | N7: B - Católica | O7: Campinas | P7: Bosque das palmeiras | R7: C - Não tenho | S7: A - Sim e faço tratamento com remédios | T7: B - Boa | U7: C - Não | V7: B - Sim, às vezes | W7: A - Sim | Z7: A - Sim | AE7: A - Sim | AF7: B - Não
A8: Nascimento em branco | B8: =VLOOKUP(C8,filtro_revisto!$A$1:$B$262,2,0) -> TRUE | C8: 26/09/2021 17:43:15 | F8: A - Sim | J8: B - Masculino | L8: A - Sim, trabalho | M8: B - Branca | N8: C - Evangélica | R8: B - Sim, mas não faço tratamento com remédios | S8: A - Sim e faço tratamento com remédios | T8: C - Regular | U8: C - Não | V8: C - Não | W8: B - Não | Z8: B - Não | AB8: B - Não | AE8: B - Não
A9: Nascimento em branco | B9: =VLOOKUP(C9,filtro_revisto!$A$1:$B$262,2,0) -> TRUE | C9: 06/10/2021 20:01:34 | D9: Sim, aceito participar da pesquisa | E9: Sirlene Rosa de Oliveira | F9: A - Sim | G9: 1999110-0209 | H9: Sirosa.jesuscristo@gmail.com | J9: A - Feminino | K9: C - Médio (ou 2º grau) | L9: A - Sim, trabalho | M9: B - Branca | N9: C - Evangélica | O9: Campinas | P9: Chácara São José | Q9: 13054-064 | R9: C - Não tenho | S9: A - Sim e faço tratamento com remédios | T9: B - Boa | U9: C - Não | V9: C - Não | W9: A - Sim | X9: E - Boa, porque familiar me ajuda | Y9: A - Sim | Z9: B - Não | AB9: B - Não | AE9: B - Não
A10: Nascimento em branco | B10: =VLOOKUP(C10,filtro_revisto!$A$1:$B$262,2,0) -> FALSE | C10: 06/10/2021 20:49:53 | D10: Sim, aceito participar da pesquisa | L10: A - Sim, trabalho | M10: B - Branca | N10: Congregação cristal do Brasil | O10: Sumare | P10: Centro | R10: C - Não tenho | S10: C - Não tenho | T10: B - Boa | U10: C - Não | V10: B - Sim, às vezes | W10: A - Sim | X10: C - Ruim, não consigo comunicação | Y10: D - Não, porque não tem Central de Interpretação de Libras na minha cidade | Z10: A - Sim | AA10: C - Ruim, não consigo comunicação | AB10: B - Não | AE10: B - Não
A11: Nascimento em branco | B11: =VLOOKUP(C11,filtro_revisto!$A$1:$B$262,2,0) -> FALSE | C11: 06/10/2021 22:23:42 | D11: Sim, aceito participar da pesquisa | E11: Lilian Caroline Sacco Sangali | K11: C - Médio (ou 2º grau) | L11: A - Sim, trabalho | M11: B - Branca | N11: B - Católica | O11: Amparo-sp | P11: Bairro parque flamboyant | Q11: 13904532 | R11: C - Não tenho | S11: C - Não tenho | T11: B - Boa | U11: C - Não | V11: C - Não | W11: A - Sim | X11: E - Boa, porque familiar me ajuda | Z11: A - Sim | AA11: E - Boa, porque familiar me ajuda | AB11: B - Não | AE11: A - Sim | AF11: B - Não
A12: Nascimento em branco | B12: =VLOOKUP(C12,filtro_revisto!$A$1:$B$262,2,0) -> FALSE | C12: 08/10/2021 20:34:59 | X12: D - Boa, tem intérprete que me ajuda
A13: Nascimento em branco | B13: =VLOOKUP(C13,filtro_revisto!$A$1:$B$262,2,0) -> FALSE | C13: 13/10/2021 19:10:17 | J13: B - Masculino | K13: B - Fundamental (ou 1º grau) | L13: A - Sim, trabalho | M13: C - Parda | N13: C - Evangélica | O13: Paulínia | P13: Bom retiro | Q13: 13142076 | R13: C - Não tenho | S13: C - Não tenho | T13: B - Boa | U13: C - Não | V13: C - Não | W13: B - Não | Z13: A - Sim | AA13: A - Ruim, não sabem LIBRAS e sou obrigado a oralizar | AB13: B - Não | AE13: B - Não
A14: Nascimento em branco | B14: =VLOOKUP(C14,filtro_revisto!$A$1:$B$262,2,0) -> FALSE | C14: 13/10/2021 23:32:18 | D14: Sim, aceito participar da pesquisa | E14: Ana | F14: B - Não | G14: 19997432999 | J14: A - Feminino | K14: D - Superior (ou 3º grau) | L14: A - Sim, trabalho | M14: B - Branca | N14: Evangélica | O14: Campinas | P14: Swiss Park | R14: C - Não tenho | S14: A - Sim e faço tratamento com remédios | T14: B - Boa | U14: C - Não | V14: C - Não | W14: A - Sim | X14: A - Ruim, não sabem LIBRAS e sou obrigado a oralizar | Z14: A - Sim | AB14: A - Sim | AC14: A - Sim | AE14: B - Não
A16: Data de nascimento preenchida de forma errada (ano 2021, ano 2022, etc…) | B16: =VLOOKUP(C16,filtro_revisto!$A$1:$B$262,2,0) -> TRUE | C16: 21/08/2021 13:24:39 | F16: A - Sim | G16: 19996755099 | H16: librascampinas@gmail.com | I16: 27/04/2022 | J16: A - Feminino | K16: E - Pós-graduação (especialização, mestrado, doutorado) | L16: A - Sim, trabalho | M16: B - Branca | N16: D - Espírita | O16: Campinas | P16: Jardim Eulina | R16: C - Não tenho | S16: A - Sim e faço tratamento com remédios | T16: C - Regular | U16: C - Não | V16: C - Não | W16: B - Não | Z16: A - Sim | AA16: A - Ruim, não sabem LIBRAS e sou obrigado a oralizar | AB16: B - Não | AE16: B - Não
B17: =VLOOKUP(C17,filtro_revisto!$A$1:$B$262,2,0) -> TRUE | C17: 22/08/2021 15:32:40 | D17: Sim, aceito participar da pesquisa | E17: Cidinha zaghetti | F17: A - Sim | G17: 19971365023 | H17: zaghetti.cidinhha@gmail.com | I17: 19/03/2016 | J17: A - Feminino | K17: D - Superior (ou 3º grau) | L17: A - Sim, trabalho | M17: B - Branca | N17: B - Católica | R17: C - Não tenho | S17: C - Não tenho | T17: B - Boa | U17: C - Não | V17: C - Não | W17: B - Não | Z17: A - Sim | AA17: D - Boa, tem intérprete que me ajuda | AB17: A - Sim | AC17: A - Sim | AD17: C - Ruim, não consigo comunicação | AE17: B - Não
B18: =VLOOKUP(C18,filtro_revisto!$A$1:$B$262,2,0) -> FALSE | C18: 01/09/2021 11:01:57 | D18: Sim, aceito participar da pesquisa | E18: Laysla Monique | F18: B - Não | G18: 19 989871632 | H18: laysla.dona@gmail.com | I18: 11/02/2021 | J18: A - Feminino | K18: E - Pós-graduação (especialização, mestrado, doutorado) | L18: A - Sim, trabalho | M18: B - Branca | O18: Campinaa | P18: Parque família | Q18: 13067763 | R18: C - Não tenho | S18: C - Não tenho | T18: E - Muito ruim | U18: C - Não | V18: C - Não | W18: B - Não | Z18: A - Sim | AA18: C - Ruim, não consigo comunicação | AB18: A - Sim | AC18: B - Não | AE18: B - Não
B19: =VLOOKUP(C19,filtro_revisto!$A$1:$B$262,2,0) -> TRUE | C19: 06/10/2021 18:42:31 | D19: Sim, aceito participar da pesquisa | E19: Tamires Vieira ds Lima | F19: A - Sim | G19: 19992593419 | H19: tamyandy2@gmail.com | I19: 20/06/2021 | J19: A - Feminino | K19: D - Superior (ou 3º grau) | L19: A - Sim, trabalho | M19: C - Parda | N19: C - Evangélica | O19: Indaiatuba | P19: jd morada do sol | Q19: 13346460 | R19: C - Não tenho | S19: C - Não tenho | T19: A - Muito boa | U19: C - Não | V19: B - Sim, às vezes | W19: A - Sim | X19: C - Ruim, não consigo comunicação | Y19: C - Não, porque não tem intérprete livre nunca | Z19: A - Sim | AA19: C - Ruim, não consigo comunicação | AB19: B - Não | AE19: B - Não
B20: =VLOOKUP(C20,filtro_revisto!$A$1:$B$262,2,0) -> TRUE | C20: 06/10/2021 18:54:12 | D20: Sim, aceito participar da pesquisa | E20: Michele de Jesus Costa e Silva | F20: A - Sim | G20: 19995252156 | H20: Michelegomesdejesus12@gmail.com | I20: 27/02/2021 | J20: A - Feminino | K20: C - Médio (ou 2º grau) | L20: A - Sim, trabalho | M20: C - Parda | N20: B - Católica | O20: Hortolandia | P20: vila São Pedro | Q20: 13183240 | R20: C - Não tenho | S20: C - Não tenho | T20: A - Muito boa | U20: C - Não | V20: C - Não | W20: A - Sim | X20: A - Ruim, não sabem LIBRAS e sou obrigado a oralizar | Y20: D - Não, porque não tem Central de Interpretação de Libras na minha cidade | Z20: A - Sim | AA20: A - Ruim, não sabem LIBRAS e sou obrigado a oralizar | AB20: B - Não | AE20: B - Não
B21: =VLOOKUP(C21,filtro_revisto!$A$1:$B$262,2,0) -> TRUE | C21: 06/10/2021 19:11:48 | D21: Sim, aceito participar da pesquisa | E21: Valter aparecido bonassi | F21: A - Sim | G21: 1993044497 | H21: bonassi.walter@gmail.com | I21: 08/04/2021 | J21: B - Masculino | K21: C - Médio (ou 2º grau) | L21: A - Sim, trabalho | M21: B - Branca | N21: C - Evangélica | O21: Campinas SP | P21: Jardim Maria Rosa | Q21: 13052400 | R21: C - Não tenho | S21: C - Não tenho | T21: B - Boa | U21: C - Não | V21: B - Sim, às vezes | W21: A - Sim | X21: C - Ruim, não consigo comunicação | Y21: C - Não, porque não tem intérprete livre nunca | Z21: A - Sim | AA21: C - Ruim, não consigo comunicação | AB21: B - Não | AE21: B - Não
B22: =VLOOKUP(C22,filtro_revisto!$A$1:$B$262,2,0) -> FALSE | C22: 07/10/2021 23:41:07 | D22: Sim, aceito participar da pesquisa | E22: Edmeire de Paula Carneiro | F22: B - Não | G22: 19 989341997 | H22: Meiguinhapaula@hotmail.com | I22: 26/11/2021 | J22: A - Feminino | K22: C - Médio (ou 2º grau) | L22: E - Não, estou desempregado | M22: C - Parda | N22: C - Evangélica | O22: Campinas sp | P22: Vila uniao | Q22: 13060701 | R22: C - Não tenho | S22: C - Não tenho | T22: E - Muito ruim | U22: C - Não | V22: C - Não | W22: A - Sim | X22: E - Boa, porque familiar me ajuda | Y22: B - Não, porque eu esqueço de pedir | Z22: A - Sim | AA22: E - Boa, porque familiar me ajuda | AB22: B - Não | AE22: B - Não
A24: Cidade não preenchida | B24: =VLOOKUP(C24,filtro_revisto!$A$1:$B$262,2,0) -> TRUE | C24: 17/08/2021 12:17:51 | D24: Sim, aceito participar da pesquisa | F24: A - Sim | I24: 19/05/2002 | J24: A - Feminino | K24: C - Médio (ou 2º grau) | L24: A - Sim, trabalho | M24: C - Parda | R24: A - Sim e faço tratamento com remédios | S24: C - Não tenho | T24: A - Muito boa | U24: C - Não | V24: C - Não | W24: A - Sim | X24: F - Boa, o profissional de saúde sabe LIBRAS | Y24: A - Sim | Z24: A - Sim | AA24: D - Boa, tem intérprete que me ajuda | AB24: A - Sim | AC24: A - Sim | AD24: B - Ruim, não sabe LIBRAS e preciso escrever português | AE24: B - Não
B25: =VLOOKUP(C25,filtro_revisto!$A$1:$B$262,2,0) -> TRUE | C25: 22/08/2021 15:32:40 | D25: Sim, aceito participar da pesquisa | E25: Cidinha zaghetti | F25: A - Sim | G25: 19971365023 | H25: zaghetti.cidinhha@gmail.com | I25: 19/03/2016 | J25: A - Feminino | K25: D - Superior (ou 3º grau) | L25: A - Sim, trabalho | M25: B - Branca | N25: B - Católica | R25: C - Não tenho | S25: C - Não tenho | T25: B - Boa | U25: C - Não | V25: C - Não | W25: B - Não | Z25: A - Sim | AA25: D - Boa, tem intérprete que me ajuda | AB25: A - Sim | AC25: A - Sim | AD25: C - Ruim, não consigo comunicação | AE25: B - Não
B26: =VLOOKUP(C26,filtro_revisto!$A$1:$B$262,2,0) -> FALSE | C26: 26/08/2021 09:26:15
B27: =VLOOKUP(C27,filtro_revisto!$A$1:$B$262,2,0) -> TRUE | C27: 26/08/2021 14:23:32 | D27: Sim, aceito participar da pesquisa | E27: Magda Angelica De Camargo | F27: A - Sim | G27: 19984241045 | H27: magdacamargo2021@gmail.com | I27: 17/03/1993 | J27: A - Feminino | K27: D - Superior (ou 3º grau) | L27: A - Sim, trabalho | M27: B - Branca | N27: B - Católica | P27: Vila vitoria | Q27: 13056758 | R27: C - Não tenho | S27: C - Não tenho | T27: A - Muito boa | U27: C - Não | V27: B - Sim, às vezes | W27: A - Sim | X27: A - Ruim, não sabem LIBRAS e sou obrigado a oralizar | Y27: A - Sim | Z27: A - Sim | AA27: A - Ruim, não sabem LIBRAS e sou obrigado a oralizar | AB27: A - Sim | AC27: B - Não | AE27: B - Não
B28: =VLOOKUP(C28,filtro_revisto!$A$1:$B$262,2,0) -> TRUE | C28: 26/09/2021 17:43:15 | F28: A - Sim | J28: B - Masculino | L28: A - Sim, trabalho | M28: B - Branca | N28: C - Evangélica | R28: B - Sim, mas não faço tratamento com remédios | S28: A - Sim e faço tratamento com remédios | T28: C - Regular | U28: C - Não | V28: C - Não | W28: B - Não | Z28: B - Não | AB28: B - Não | AE28: B - Não
B29: =VLOOKUP(C29,filtro_revisto!$A$1:$B$262,2,0) -> FALSE | C29: 08/10/2021 20:34:59 | X29: D - Boa, tem intérprete que me ajuda
B30: =VLOOKUP(C30,filtro_revisto!$A$1:$B$262,2,0) -> TRUE | C30: 09/10/2021 21:46:04 | D30: Sim, aceito participar da pesquisa | E30: luzia gomes de oliveira | F30: A - Sim | G30: 19987158570 | H30: lu_zia_barretos@hotmail.com | I30: 13/12/1969 | J30: A - Feminino | K30: B - Fundamental (ou 1º grau) | L30: E - Não, estou desempregado | M30: B - Branca | N30: igreja do nazareno | Q30: 13105-566 | R30: C - Não tenho | S30: C - Não tenho | T30: B - Boa | U30: C - Não | V30: C - Não | W30: B - Não | Z30: A - Sim | AA30: D - Boa, tem intérprete que me ajuda | AB30: B - Não | AE30: B - Não
A32: usa SUS, mas não avaliou a comunicação paciente-médico | B32: =VLOOKUP(C32,filtro_revisto!$A$1:$B$262,2,0) -> FALSE | C32: 22/09/2021 16:52:01 | D32: Sim, aceito participar da pesquisa | F32: B - Não | G32: 19991562380 | H32: ronerdw@hotmail.com | I32: 21/03/1962 | J32: B - Masculino | K32: D - Superior (ou 3º grau) | L32: C - Não, porque sou aposentado | M32: B - Branca | N32: D - Espírita | O32: Campinas | P32: Jd. Aurelia | Q32: 13033740 | R32: C - Não tenho | S32: A - Sim e faço tratamento com remédios | T32: A - Muito boa | U32: C - Não | V32: B - Sim, às vezes | W32: A - Sim | Z32: B - Não | AB32: A - Sim | AC32: B - Não | AE32: A - Sim | AF32: B - Não
B33: =VLOOKUP(C33,filtro_revisto!$A$1:$B$262,2,0) -> FALSE | C33: 22/09/2021 16:55:45 | D33: Sim, aceito participar da pesquisa | E33: Antonia Carmen Martínez Magnusson | F33: B - Não | G33: 19992679599 | H33: bosquespal@gmail.com | J33: A - Feminino | K33: E - Pós-graduação (especialização, mestrado, doutorado) | L33: A - Sim, trabalho | M33: B - Branca | N33: B - Católica | O33: Campinas | P33: Bosque das palmeiras | R33: C - Não tenho | S33: A - Sim e faço tratamento com remédios | T33: B - Boa | U33: C - Não | V33: B - Sim, às vezes | W33: A - Sim | Z33: A - Sim | AE33: A - Sim | AF33: B - Não
B34: =VLOOKUP(C34,filtro_revisto!$A$1:$B$262,2,0) -> FALSE | C34: 06/10/2021 19:25:44 | D34: Sim, aceito participar da pesquisa | E34: Williamar Santos de Almeida | F34: A - Sim | G34: 19995574512 | H34: williamarster79@gmail.com | I34: 11/05/1979 | J34: B - Masculino | K34: C - Médio (ou 2º grau) | L34: B - Não trabalho e recebo benefício BPC/INSS | M34: C - Parda | N34: B - Católica | O34: Goiânia Goiás | P34: Jardim Itaipu | Q34: 74355528 | R34: C - Não tenho | S34: A - Sim e faço tratamento com remédios | T34: A - Muito boa | U34: C - Não | V34: B - Sim, às vezes | W34: A - Sim | Z34: B - Não | AB34: B - Não | AE34: B - Não
B35: =VLOOKUP(C35,filtro_revisto!$A$1:$B$262,2,0) -> TRUE | C35: 06/10/2021 22:51:42 | E35: Emerson Diego de Sá | F35: A - Sim | G35: 19996166020 | H35: Emersondiego0607@gmail.com | I35: 06/07/1990 | J35: B - Masculino | K35: C - Médio (ou 2º grau) | L35: A - Sim, trabalho | M35: C - Parda | N35: A - Não tenho religião | O35: Hortolândia | P35: Jardim Amanda I | Q35: 13188-130 | R35: C - Não tenho | S35: C - Não tenho | T35: B - Boa | U35: C - Não | W35: A - Sim | Z35: A - Sim | AB35: A - Sim | AC35: A - Sim | AE35: B - Não
B36: =VLOOKUP(C36,filtro_revisto!$A$1:$B$262,2,0) -> FALSE | C36: 07/10/2021 16:18:40 | H36: Gisele25sol@gmail.com | I36: 21/11/1991 | J36: A - Feminino | K36: D - Superior (ou 3º grau) | L36: B - Não trabalho e recebo benefício BPC/INSS | M36: B - Branca | N36: C - Evangélica | O36: Campinas sp | R36: A - Sim e faço tratamento com remédios | S36: A - Sim e faço tratamento com remédios | T36: C - Regular | U36: C - Não | V36: C - Não | W36: A - Sim | Z36: A - Sim | AB36: B - Não | AE36: B - Não
A38: usa rede particular, mas não avaliou a comunicação paciente-médico | B38: =VLOOKUP(C38,filtro_revisto!$A$1:$B$262,2,0) -> FALSE | C38: 23/08/2021 08:10:25 | D38: Sim, aceito participar da pesquisa | E38: Tatiana Schmidt-Hebbel Pedrazzoli | F38: B - Não | G38: 19991930201 | H38: tati_schebbel@hotmail.com | I38: 15/12/1989 | J38: A - Feminino | K38: E - Pós-graduação (especialização, mestrado, doutorado) | L38: E - Não, estou desempregado | M38: B - Branca | N38: A - Não tenho religião | O38: Campinas | R38: C - Não tenho | S38: C - Não tenho | T38: B - Boa | U38: C - Não | V38: C - Não | W38: B - Não | Z38: A - Sim | AB38: A - Sim | AC38: B - Não | AE38: A - Sim | AF38: B - Não
B39: =VLOOKUP(C39,filtro_revisto!$A$1:$B$262,2,0) -> FALSE | C39: 23/08/2021 08:17:06 | D39: Sim, aceito participar da pesquisa | E39: Antonia Carmen Martínez Magnusson | F39: B - Não | H39: bosquespal@gmail.com | I39: 13/06/1957 | J39: A - Feminino | K39: D - Superior (ou 3º grau) | L39: A - Sim, trabalho | M39: B - Branca | N39: B - Católica | O39: Campinas | P39: Bosque das palmeiras | R39: C - Não tenho | S39: A - Sim e faço tratamento com remédios | T39: C - Regular | U39: C - Não | V39: B - Sim, às vezes | W39: A - Sim | X39: C - Ruim, não consigo comunicação | Y39: D - Não, porque não tem Central de Interpretação de Libras na minha cidade | Z39: A - Sim | AE39: A - Sim | AF39: B - Não
B40: =VLOOKUP(C40,filtro_revisto!$A$1:$B$262,2,0) -> TRUE | C40: 23/08/2021 13:04:40 | D40: Sim, aceito participar da pesquisa | E40: Marjorie Vieira Rocha | F40: A - Sim | G40: 19 996880078 | H40: marjorierocha43@hotmail.com | I40: 07/11/1968 | J40: A - Feminino | K40: D - Superior (ou 3º grau) | L40: A - Sim, trabalho | M40: C - Parda | N40: D - Espírita | O40: Campinas | P40: Centro | Q40: 13015080 | R40: C - Não tenho | S40: C - Não tenho | T40: A - Muito boa | U40: C - Não | V40: B - Sim, às vezes | W40: B - Não | Z40: A - Sim | AB40: A - Sim | AC40: B - Não | AE40: A - Sim | AF40: B - Não
B41: =VLOOKUP(C41,filtro_revisto!$A$1:$B$262,2,0) -> FALSE | C41: 23/08/2021 13:38:13 | D41: Sim, aceito participar da pesquisa | E41: Rodrigo Andrade Rabelo | F41: B - Não | G41: 19992362766 | H41: rodrigorabelo@gmail.com | I41: 12/12/1983 | J41: B - Masculino | K41: D - Superior (ou 3º grau) | L41: A - Sim, trabalho | M41: B - Branca | N41: D - Espírita | O41: Paulínia | P41: Jardim Europa | R41: C - Não tenho | S41: C - Não tenho | T41: A - Muito boa | U41: C - Não | V41: C - Não | W41: B - Não | Z41: A - Sim | AB41: B - Não | AE41: A - Sim | AF41: B - Não
B42: =VLOOKUP(C42,filtro_revisto!$A$1:$B$262,2,0) -> FALSE | C42: 27/08/2021 13:25:27 | D42: Sim, aceito participar da pesquisa | E42: Regina Fernandes Pinheiro Lucas | F42: B - Não | G42: 19992529219 | H42: relucas@unicamp.br | I42: 15/01/1958 | J42: A - Feminino | K42: D - Superior (ou 3º grau) | L42: A - Sim, trabalho | M42: B - Branca | N42: B - Católica | O42: Jundiaí | P42: Bairro Medeiros | Q42: 13.212-265 | R42: C - Não tenho | S42: B - Sim, mas não faço tratamento com remédios | T42: C - Regular | U42: C - Não | V42: C - Não | W42: B - Não | Z42: A - Sim | AB42: A - Sim | AC42: B - Não | AE42: B - Não
B43: =VLOOKUP(C43,filtro_revisto!$A$1:$B$262,2,0) -> FALSE | C43: 22/09/2021 16:55:45 | D43: Sim, aceito participar da pesquisa | E43: Antonia Carmen Martínez Magnusson | F43: B - Não | G43: 19992679599 | H43: bosquespal@gmail.com | J43: A - Feminino | K43: E - Pós-graduação (especialização, mestrado, doutorado) | L43: A - Sim, trabalho | M43: B - Branca | N43: B - Católica | O43: Campinas | P43: Bosque das palmeiras | R43: C - Não tenho | S43: A - Sim e faço tratamento com remédios | T43: B - Boa | U43: C - Não | V43: B - Sim, às vezes | W43: A - Sim | Z43: A - Sim | AE43: A - Sim | AF43: B - Não
B44: =VLOOKUP(C44,filtro_revisto!$A$1:$B$262,2,0) -> TRUE | C44: 06/10/2021 19:12:40 | E44: Augusto Eduardo PATERNO CRISCIONE | F44: A - Sim | G44: 19984240636 | H44: gucris4@gmail.com | I44: 31/08/1969 | J44: B - Masculino | K44: D - Superior (ou 3º grau) | L44: A - Sim, trabalho | M44: B - Branca | O44: Campinas | P44: Parque eucaliptos | Q44: 13061-371 | R44: C - Não tenho | S44: C - Não tenho | T44: B - Boa | U44: C - Não | V44: C - Não | W44: B - Não | Z44: A - Sim | AB44: A - Sim | AC44: B - Não | AE44: B - Não
B45: =VLOOKUP(C45,filtro_revisto!$A$1:$B$262,2,0) -> TRUE | C45: 06/10/2021 22:51:42 | E45: Emerson Diego de Sá | F45: A - Sim | G45: 19996166020 | H45: Emersondiego0607@gmail.com | I45: 06/07/1990 | J45: B - Masculino | K45: C - Médio (ou 2º grau) | L45: A - Sim, trabalho | M45: C - Parda | N45: A - Não tenho religião | O45: Hortolândia | P45: Jardim Amanda I | Q45: 13188-130 | R45: C - Não tenho | S45: C - Não tenho | T45: B - Boa | U45: C - Não | W45: A - Sim | Z45: A - Sim | AB45: A - Sim | AC45: A - Sim | AE45: B - Não
...

Sheet Base_original_até_20.10.2021
A1: Carimbo de data/hora | B1: Consentimento livre e esclarecido: Após ter sido esclarecido sobre a natureza da pesquisa, seus objetivos, métodos, benefícios previstos, potenciais riscos e o incômodo que esta possa acarretar, aceito participar do preenchimento do questionário, disponível no Google Forms. | C1: Nome completo do participante | D1: Você se comunica por LIBRAS, tem 18 anos ou mais e mora em alguma das cidades do mapa? | E1: Qual é o número do seu telefone celular com DDD? | F1: Qual é o seu e-mail? | G1: Qual é a sua data de nascimento? | H1: Qual é o seu sexo? | I1: Qual é a sua escolaridade? | J1: Você trabalha? | K1: Qual é a sua cor (ou raça)? | L1: Qual sua religião? | M1: Qual cidade você mora? | N1: Qual bairro você mora? | O1: Qual número do seu CEP? | P1: Você tem diabetes? | Q1: Você tem pressão alta? | R1: Qual é a sua opinião sobre sua saúde? | S1: Você fuma? | T1: Você toma bebidas alcoólicas? | U1: Você usa os serviços de saúde do SUS, por exemplo, centros de saúde, hospitais, exames e vários outros serviços de saúde? | V1: Quando você vai aos serviços de saúde do SUS como você avalia a comunicação com médicos, enfermeiros e diversos profissionais nestes serviços? | W1: O intérprete da Central de Interpretação de Libras (CIL) vai no atendimento com você no serviço público de saúde SUS? | X1: Você usa a rede particular de saúde? Exemplo: hospital, médico, convênio | Y1: Como você avalia a comunicação entre você e o profissional de saúde do convênio ou na rede particular, com médicos, enfermeiros e diversos outros profissionais, como é a comunicação? | Z1: Você usa aparelho auditivo? | AA1: Você conseguiu seu aparelho auditivo pelo SUS? | AB1: Como você avalia a comunicação entre você e o médico, a fonoaudióloga e os diversos outros profissionais do centro do SUS onde conseguiu o aparelho auditivo? | AC1: Você usa implante coclear? | AD1: Você conseguiu seu implante coclear pelo SUS? | AE1: Como você avalia a comunicação entre você e o médico, a fonoaudióloga e os diversos outros profissionais do centro do SUS onde conseguiu o implante coclear?
A2: 16/08/2021 20:23:13 | B2: Sim, aceito participar da pesquisa | C2: Gabriene Alves de Azevedo Monteiro | D2: A - Sim | E2: 19987065350 | F2: monteirogabriene@gmail.com | G2: 23/04/1989 | H2: A - Feminino | I2: D - Superior (ou 3º grau) | J2: A - Sim, trabalho | K2: B - Branca | L2: B - Católica | M2: Sumaré | N2: Jardim Recanto dos Sonhos | O2: 13178724 | P2: C - Não tenho | Q2: C - Não tenho | R2: B - Boa | S2: C - Não | T2: C - Não | U2: A - Sim | V2: E - Boa, porque familiar me ajuda | W2: B - Não, porque eu esqueço de pedir | X2: A - Sim | Y2: E - Boa, porque familiar me ajuda | Z2: A - Sim | AA2: A - Sim | AB2: E - Boa, porque familiar me ajuda | AC2: A - Sim | AD2: A - Sim | AE2: E - Boa, porque familiar me ajuda
A3: 17/08/2021 12:17:51 | B3: Sim, aceito participar da pesquisa | D3: A - Sim | G3: 19/05/2002 | H3: A - Feminino | I3: C - Médio (ou 2º grau) | J3: A - Sim, trabalho | K3: C - Parda | P3: A - Sim e faço tratamento com remédios | Q3: C - Não tenho | R3: A - Muito boa | S3: C - Não | T3: C - Não | U3: A - Sim | V3: F - Boa, o profissional de saúde sabe LIBRAS | W3: A - Sim | X3: A - Sim | Y3: D - Boa, tem intérprete que me ajuda | Z3: A - Sim | AA3: A - Sim | AB3: B - Ruim, não sabe LIBRAS e preciso escrever português | AC3: B - Não
A4: 17/08/2021 12:37:32 | B4: Sim, aceito participar da pesquisa | C4: Monica Fernanda Baldin Marques | D4: A - Sim | E4: 19983798677 | F4: monicasurda28@gmail.com | G4: 07/05/1979 | H4: A - Feminino | I4: C - Médio (ou 2º grau) | J4: E - Não, estou desempregado | K4: B - Branca | L4: C - Evangélica | M4: Campinas-SP | N4: CHUD Edivaldo Orsi | O4: 13069-077 | P4: C - Não tenho | Q4: C - Não tenho | R4: D - Ruim | S4: C - Não | T4: C - Não | U4: A - Sim | V4: C - Ruim, não consigo comunicação | W4: B - Não, porque eu esqueço de pedir | X4: A - Sim | Y4: C - Ruim, não consigo comunicação | Z4: B - Não | AC4: B - Não
A5: 17/08/2021 16:53:13 | B5: Sim, aceito participar da pesquisa | C5: ROSEMEIRE APARECIDA ANTUNES DESIDERIO | D5: A - Sim | E5: 19995521694 | F5: roseadesiderio@gmail.com | G5: 11/07/1971 | H5: A - Feminino | I5: E - Pós-graduação (especialização, mestrado, doutorado) | J5: A - Sim, trabalho | K5: B - Branca | L5: C - Evangélica | M5: Hortolândia | N5: Jardim Amanda I | O5: 13188010 | P5: C - Não tenho | Q5: A - Sim e faço tratamento com remédios | R5: B - Boa | S5: C - Não | T5: C - Não | U5: A - Sim | V5: A - Ruim, não sabem LIBRAS e sou obrigado a oralizar | W5: D - Não, porque não tem Central de Interpretação de Libras na minha cidade | X5: A - Sim | Y5: A - Ruim, não sabem LIBRAS e sou obrigado a oralizar | Z5: A - Sim | AA5: A - Sim | AB5: E - Boa, porque familiar me ajuda | AC5: B - Não
A6: 17/08/2021 17:35:36 | B6: Sim, aceito participar da pesquisa | C6: Sabrina Alves de Oliveira | D6: A - Sim | E6: 11 97487-1125 | F6: Sabrina.niguima@gmail.com | G6: 09/08/1987 | H6: A - Feminino | I6: C - Médio (ou 2º grau) | J6: E - Não, estou desempregado | K6: B - Branca | L6: C - Evangélica | M6: Campinas | N6: Jardim do Lago Continuação | O6: 13051-028 | P6: C - Não tenho | Q6: C - Não tenho | R6: B - Boa | S6: C - Não | T6: C - Não | U6: A - Sim | V6: A - Ruim, não sabem LIBRAS e sou obrigado a oralizar | W6: A - Sim | X6: B - Não | Z6: B - Não | AC6: B - Não
A7: 17/08/2021 20:13:30 | B7: Sim, aceito participar da pesquisa | D7: A - Sim | G7: 20/05/1990 | H7: B - Masculino | I7: D - Superior (ou 3º grau) | J7: A - Sim, trabalho | K7: B - Branca | L7: B - Católica | M7: Campinas-SP | N7: Villa Garden | O7: 13031365 | P7: C - Não tenho | Q7: C - Não tenho | R7: A - Muito boa | S7: C - Não | T7: C - Não | U7: B - Não | X7: A - Sim | Y7: A - Ruim, não sabem LIBRAS e sou obrigado a oralizar | Z7: B - Não | AC7: B - Não
A8: 17/08/2021 20:29:52 | B8: Sim, aceito participar da pesquisa | C8: Rafaela Cristina Machado | D8: A - Sim | E8: (19)983320259 | F8: fafa_cristina92@hotmail.com | G8: 17/04/1992 | H8: A - Feminino | I8: D - Superior (ou 3º grau) | J8: E - Não, estou desempregado | K8: C - Parda | M8: Sumaré-SP | N8: Parque Residencial Salerno | O8: 13178-353 | P8: C - Não tenho | Q8: C - Não tenho | R8: C - Regular | S8: C - Não | T8: B - Sim, às vezes | U8: A - Sim | V8: C - Ruim, não consigo comunicação | W8: D - Não, porque não tem Central de Interpretação de Libras na minha cidade | X8: B - Não | Z8: B - Não | AC8: B - Não
A9: 17/08/2021 20:56:37 | B9: Sim, aceito participar da pesquisa | C9: Caio L Oliveira | D9: A - Sim | E9: 19999114458 | F9: caiooliver182@gmail.com | G9: 09/03/1991 | H9: B - Masculino | I9: E - Pós-graduação (especialização, mestrado, doutorado) | J9: A - Sim, trabalho | K9: C - Parda | L9: A - Não tenho religião | M9: Campinas | N9: Barão Geraldo | O9: 13083-480 | P9: C - Não tenho | Q9: C - Não tenho | R9: A - Muito boa | S9: C - Não | T9: B - Sim, às vezes | U9: B - Não | X9: A - Sim | Y9: F - Boa, o profissional de saúde sabe LIBRAS | Z9: A - Sim | AA9: B - Não | AC9: A - Sim | AD9: A - Sim | AE9: B - Ruim, não sabe LIBRAS e preciso escrever português
A10: 17/08/2021 21:24:13 | B10: Sim, aceito participar da pesquisa | C10: Regilena Maria de Faria Tosta | D10: A - Sim | E10: 1999610-5431 | F10: regitosta@yahoo.com.br | G10: 21/12/1961 | H10: A - Feminino | I10: D - Superior (ou 3º grau) | J10: C - Não, porque sou aposentado | K10: B - Branca | L10: B - Católica | M10: Paulinia | N10: Jardim Calegaris | O10: 13140-121 | P10: C - Não tenho | Q10: A - Sim e faço tratamento com remédios | R10: B - Boa | S10: C - Não | T10: B - Sim, às vezes | U10: B - Não | X10: A - Sim | Y10: E - Boa, porque familiar me ajuda | Z10: B - Não | AC10: A - Sim | AD10: A - Sim | AE10: E - Boa, porque familiar me ajuda
A11: 17/08/2021 23:05:23 | B11: Sim, aceito participar da pesquisa | C11: Alexssandro Silva da Fonseca | D11: B - Não | E11: 19998651710 | F11: sandrinhosurdo@gmail.com | G11: 17/10/1986 | H11: B - Masculino | I11: E - Pós-graduação (especialização, mestrado, doutorado) | J11: A - Sim, trabalho | K11: C - Parda | L11: C - Evangélica | M11: Iracemápolis | N11: Res. Aquarius | O11: 13495-000 | P11: C - Não tenho | Q11: C - Não tenho | R11: B - Boa | S11: C - Não | T11: C - Não | U11: A - Sim | V11: E - Boa, porque familiar me ajuda | W11: D - Não, porque não tem Central de Interpretação de Libras na minha cidade | X11: A - Sim | Y11: E - Boa, porque familiar me ajuda | Z11: B - Não | AC11: B - Não
A12: 17/08/2021 23:21:46 | B12: Sim, aceito participar da pesquisa | C12: Tiago Luiz Miranda de Freitas | D12: A - Sim | G12: 03/07/1989 | H12: B - Masculino | I12: E - Pós-graduação (especialização, mestrado, doutorado) | J12: E - Não, estou desempregado | K12: B - Branca | L12: C - Evangélica | M12: Santa Bárbara d'Oeste/SP | N12: São Joaquim | O12: 13453115 | P12: C - Não tenho | Q12: C - Não tenho | R12: A - Muito boa | S12: C - Não | T12: C - Não | U12: B - Não | X12: B - Não | Z12: B - Não | AC12: B - Não
A13: 17/08/2021 23:35:59 | B13: Sim, aceito participar da pesquisa | C13: Luciana Aguera Rosa | D13: A - Sim | E13: 19993954343 | F13: luciana.aguerosa@gmail.com | H13: A - Feminino | I13: E - Pós-graduação (especialização, mestrado, doutorado) | J13: A - Sim, trabalho | K13: B - Branca | L13: D - Espírita | M13: Campinas | N13: Parque Brasília | O13: 13091-464 | P13: C - Não tenho | Q13: C - Não tenho | R13: B - Boa | S13: C - Não | T13: B - Sim, às vezes | U13: B - Não | X13: A - Sim | Y13: B - Ruim, não sabem LIBRAS e preciso escrever português | Z13: B - Não | AC13: B - Não
A14: 18/08/2021 07:23:44 | B14: Sim, aceito participar da pesquisa | C14: Patrícia Hipolito de Alexandria | D14: A - Sim | E14: 19 | F14: pattyxandria@yahoo.com.br | G14: 04/10/1971 | H14: A - Feminino | I14: E - Pós-graduação (especialização, mestrado, doutorado) | J14: A - Sim, trabalho | K14: B - Branca | L14: D - Espírita | M14: Campinas | N14: Vila Mimosa | O14: 13050-045 | P14: C - Não tenho | Q14: C - Não tenho | R14: B - Boa | S14: C - Não | T14: C - Não | U14: A - Sim | V14: B - Ruim, não sabem LIBRAS e preciso escrever português | W14: C - Não, porque não tem intérprete livre nunca | X14: B - Não | Z14: B - Não | AC14: B - Não
A15: 18/08/2021 07:39:08 | C15: Eliete Francisca de Oliveira | D15: B - Não | E15: 19995827971 | F15: luhribeiro1972@gmail.com | G15: 03/11/1953 | H15: A - Feminino | I15: A - Nunca estudei | J15: C - Não, porque sou aposentado | K15: C - Parda | L15: B - Católica | M15: Campinas SP | N15: Dic IV | O15: 13054 442 | P15: C - Não tenho | Q15: A - Sim e faço tratamento com remédios | R15: C - Regular | S15: C - Não | T15: B - Sim, às vezes | U15: A - Sim | V15: C - Ruim, não consigo comunicação | X15: B - Não | Z15: B - Não | AC15: B - Não
A16: 18/08/2021 09:34:22 | B16: Sim, aceito participar da pesquisa | C16: Monica Amaral Azevedo | D16: A - Sim | E16: 19 992916519 | F16: maa1967@gmail.com | G16: 19/08/1967 | H16: A - Feminino | I16: C - Médio (ou 2º grau) | J16: A - Sim, trabalho | K16: B - Branca | L16: B - Católica | M16: Campinas | N16: Bosque | O16: 13026055 | P16: C - Não tenho | Q16: A - Sim e faço tratamento com remédios | R16: B - Boa | S16: C - Não | T16: C - Não | U16: A - Sim | V16: A - Ruim, não sabem LIBRAS e sou obrigado a oralizar | W16: B - Não, porque eu esqueço de pedir | X16: A - Sim | Y16: A - Ruim, não sabem LIBRAS e sou obrigado a oralizar | Z16: A - Sim | AA16: A - Sim | AB16: A - Ruim, não sabe LIBRAS e sou obrigado a oralizar | AC16: B - Não
A17: 18/08/2021 10:38:56 | B17: Sim, aceito participar da pesquisa | C17: ADÃO APARECIDO DE CELIS | D17: A - Sim | G17: 01/01/1980 | H17: B - Masculino | I17: A - Nunca estudei | J17: B - Não trabalho e recebo benefício BPC/INSS | K17: B - Branca | L17: C - Evangélica | M17: Campinas | N17: BAIRRO DOS AMA | O17: 13069-421 | P17: C - Não tenho | Q17: C - Não tenho | R17: B - Boa | S17: C - Não | T17: B - Sim, às vezes | U17: A - Sim | V17: D - Boa, tem intérprete que me ajuda | W17: A - Sim | X17: A - Sim | Y17: E - Boa, porque familiar me ajuda | Z17: A - Sim | AA17: A - Sim | AB17: E - Boa, porque familiar me ajuda | AC17: B - Não
A18: 18/08/2021 10:50:45 | B18: Sim, aceito participar da pesquisa | C18: Lucimar Desiderio | D18: A - Sim | E18: 19993648096 | F18: roseaacademico@gmail.com | G18: 08/05/1960 | H18: B - Masculino | I18: B - Fundamental (ou 1º grau) | J18: C - Não, porque sou aposentado | K18: B - Branca | L18: C - Evangélica | M18: Hortolândia | N18: Jardim Amanda I | O18: 13188010 | P18: A - Sim e faço tratamento com remédios | Q18: A - Sim e faço tratamento com remédios | R18: B - Boa | S18: C - Não | T18: C - Não | U18: A - Sim | V18: E - Boa, porque familiar me ajuda | W18: D - Não, porque não tem Central de Interpretação de Libras na minha cidade | X18: A - Sim | Y18: E - Boa, porque familiar me ajuda | Z18: B - Não | AC18: B - Não
A19: 18/08/2021 11:45:22 | B19: Sim, aceito participar da pesquisa | C19: Fabio Antônio de Oliveira | D19: A - Sim | E19: 19 992660098 | F19: fabio15toni@gmail.com | G19: 15/01/1984 | H19: B - Masculino | I19: D - Superior (ou 3º grau) | J19: C - Não, porque sou aposentado | K19: B - Branca | L19: C - Evangélica | M19: Campinas | N19: Jardim do vovô | O19: 13033210 | P19: C - Não tenho | Q19: C - Não tenho | R19: D - Ruim | S19: C - Não | T19: C - Não | U19: A - Sim | V19: C - Ruim, não consigo comunicação | W19: C - Não, porque não tem intérprete livre nunca | X19: B - Não | Z19: B - Não | AC19: B - Não
A20: 18/08/2021 13:27:47 | B20: Sim, aceito participar da pesquisa | C20: Iara | D20: A - Sim | E20: 19 992883669 | F20: Deniseyaradesouzalgrs@gmail.com | G20: 25/06/1986 | H20: A - Feminino | I20: C - Médio (ou 2º grau) | J20: E - Não, estou desempregado | K20: C - Parda | L20: C - Evangélica | M20: Valinhos | N20: Parque das colinas | O20: 13273640 | P20: C - Não tenho | Q20: C - Não tenho | R20: B - Boa | S20: C - Não | T20: B - Sim, às vezes | U20: A - Sim | V20: A - Ruim, não sabem LIBRAS e sou obrigado a oralizar | W20: D - Não, porque não tem Central de Interpretação de Libras na minha cidade | X20: A - Sim | Y20: E - Boa, porque familiar me ajuda | Z20: A - Sim | AA20: A - Sim | AB20: E - Boa, porque familiar me ajuda | AC20: B - Não
A21: 18/08/2021 13:46:46 | D21: A - Sim | E21: 19996442141 | F21: Yuripedagogia740@gmail.com | G21: 01/01/1990 | H21: B - Masculino | I21: D - Superior (ou 3º grau) | J21: A - Sim, trabalho | K21: B - Branca | L21: A - Não tenho religião | M21: Jaguariúna | N21: Bela visita | O21: 91311418 | P21: C - Não tenho | Q21: C - Não tenho | R21: A - Muito boa | S21: C - Não | T21: C - Não | U21: A - Sim | V21: B - Ruim, não sabem LIBRAS e preciso escrever português | W21: C - Não, porque não tem intérprete livre nunca | X21: B - Não | Z21: B - Não | AC21: B - Não
A22: 18/08/2021 14:09:05 | B22: Sim, aceito participar da pesquisa | C22: Rosane Cardoso de Sousa | D22: B - Não | E22: 19991279373 | F22: rosanecsousa@hotmail.com | G22: 09/11/1980 | H22: A - Feminino | I22: E - Pós-graduação (especialização, mestrado, doutorado) | J22: A - Sim, trabalho | K22: B - Branca | L22: C - Evangélica | M22: Hortolândia | N22: Jardim minda | O22: 13184677 | P22: C - Não tenho | Q22: C - Não tenho | R22: C - Regular | S22: C - Não | T22: B - Sim, às vezes | U22: A - Sim | V22: B - Ruim, não sabem LIBRAS e preciso escrever português | W22: D - Não, porque não tem Central de Interpretação de Libras na minha cidade | X22: B - Não | Z22: B - Não | AC22: B - Não
A23: 18/08/2021 14:16:54 | B23: Sim, aceito participar da pesquisa | C23: Andréa Luísa Borin | D23: A - Sim | E23: 19981407668 | F23: deia.borin@outlook.com | G23: 15/10/1987 | H23: A - Feminino | I23: D - Superior (ou 3º grau) | J23: E - Não, estou desempregado | K23: B - Branca | L23: Deus | M23: Valinhos | N23: Vila boa esperança | O23: 13270372 | P23: C - Não tenho | Q23: C - Não tenho | R23: B - Boa | S23: A - Sim, todos os dias | T23: B - Sim, às vezes | U23: A - Sim | V23: A - Ruim, não sabem LIBRAS e sou obrigado a oralizar | W23: D - Não, porque não tem Central de Interpretação de Libras na minha cidade | X23: B - Não | Z23: A - Sim | AA23: A - Sim | AB23: E - Boa, porque familiar me ajuda | AC23: B - Não
A24: 18/08/2021 14:20:10 | B24: Sim, aceito participar da pesquisa | C24: Alexandre Luis da Silva | D24: A - Sim | E24: 19999951983 | F24: inter2020alexandre@gmail.com | G24: 08/02/1983 | H24: B - Masculino | I24: D - Superior (ou 3º grau) | J24: E - Não, estou desempregado | K24: B - Branca | L24: C - Evangélica | M24: Jaguariúna | N24: Vila Guilherme | O24: 13917002 | P24: A - Sim e faço tratamento com remédios | Q24: C - Não tenho | R24: B - Boa | S24: C - Não | T24: C - Não | U24: A - Sim | V24: F - Boa, o profissional de saúde sabe LIBRAS | W24: C - Não, porque não tem intérprete livre nunca | X24: A - Sim | Y24: B - Ruim, não sabem LIBRAS e preciso escrever português | Z24: B - Não | AC24: B - Não
A25: 18/08/2021 16:45:12 | B25: Sim, aceito participar da pesquisa | C25: Paulo Rodrigues de Siqueira | D25: A - Sim | E25: 19988321533 | F25: paulosiqueira471@hotmail.com | G25: 25/01/1964 | H25: B - Masculino | I25: B - Fundamental (ou 1º grau) | J25: A - Sim, trabalho | K25: B - Branca | L25: Adventista 7 dia | M25: Hortolandia | N25: Parque Ortolandia | O25: 13184170 | P25: C - Não tenho | Q25: C - Não tenho | R25: B - Boa | S25: C - Não | T25: C - Não | U25: A - Sim | V25: C - Ruim, não consigo comunicação | W25: D - Não, porque não tem Central de Interpretação de Libras na minha cidade | X25: A - Sim | Y25: C - Ruim, não consigo comunicação | Z25: B - Não | AC25: B - Não
A26: 18/08/2021 16:48:06 | B26: Sim, aceito participar da pesquisa | C26: Elaine Cristina do Prado Siqueira | D26: A - Sim | E26: 19981201344 | F26: elainecpsiqueiraa@hotmail.com | G26: 25/03/1967 | H26: A - Feminino | I26: C - Médio (ou 2º grau) | J26: A - Sim, trabalho | K26: B - Branca | L26: Adventista 7 dia | M26: Hortolandia | N26: Parque Ortolandia | O26: 13184170 | P26: C - Não tenho | Q26: C - Não tenho | R26: B - Boa | S26: C - Não | T26: C - Não | U26: A - Sim | V26: A - Ruim, não sabem LIBRAS e sou obrigado a oralizar | W26: D - Não, porque não tem Central de Interpretação de Libras na minha cidade | X26: A - Sim | Y26: A - Ruim, não sabem LIBRAS e sou obrigado a oralizar | Z26: B - Não | AC26: B - Não
A27: 18/08/2021 19:21:16 | B27: Sim, aceito participar da pesquisa | D27: B - Não | E27: 19991039177 | F27: rosanaapm2009@hotmail.com | G27: 10/06/2003 | H27: A - Feminino | I27: C - Médio (ou 2º grau) | J27: D - Não, porque sou estudante | K27: B - Branca | L27: B - Católica | M27: Capivari SP | N27: Jardim santo Antônio | O27: 13360000 | P27: C - Não tenho | Q27: C - Não tenho | R27: B - Boa | S27: C - Não | T27: C - Não | U27: A - Sim | V27: E - Boa, porque familiar me ajuda | W27: D - Não, porque não tem Central de Interpretação de Libras na minha cidade | X27: B - Não | Z27: A - Sim | AA27: B - Não | AC27: B - Não
A28: 18/08/2021 20:48:51 | B28: Sim, aceito participar da pesquisa | C28: Leandro Almeida Leite | D28: A - Sim | E28: 11969052681 | F28: lleite.inclusao@gmail.com | G28: 29/06/1979 | H28: B - Masculino | I28: E - Pós-graduação (especialização, mestrado, doutorado) | J28: E - Não, estou desempregado | K28: B - Branca | L28: B - Católica | M28: Jaguariúna | N28: Vargeão | O28: 13915-001 | P28: C - Não tenho | Q28: C - Não tenho | R28: A - Muito boa | S28: C - Não | T28: C - Não | U28: A - Sim | V28: A - Ruim, não sabem LIBRAS e sou obrigado a oralizar | W28: D - Não, porque não tem Central de Interpretação de Libras na minha cidade | X28: B - Não | Z28: A - Sim | AA28: A - Sim | AB28: A - Ruim, não sabe LIBRAS e sou obrigado a oralizar | AC28: B - Não
A29: 18/08/2021 21:21:58 | B29: Sim, aceito participar da pesquisa | C29: Bruno cezar crispim pereira | D29: A - Sim | E29: 19984490664 | F29: bcezar86@gmail.com | G29: 24/12/1986 | H29: B - Masculino | I29: E - Pós-graduação (especialização, mestrado, doutorado) | J29: A - Sim, trabalho | K29: B - Branca | L29: A - Não tenho religião | M29: Campinas | N29: Jardim novo Maracanã | O29: 13058413 | P29: C - Não tenho | Q29: C - Não tenho | R29: A - Muito boa | S29: C - Não | T29: C - Não | U29: A - Sim | V29: B - Ruim, não sabem LIBRAS e preciso escrever português | W29: C - Não, porque não tem intérprete livre nunca | X29: A - Sim | Y29: B - Ruim, não sabem LIBRAS e preciso escrever português | Z29: A - Sim | AA29: B - Não | AC29: B - Não
A30: 18/08/2021 21:46:24 | B30: Sim, aceito participar da pesquisa | C30: Otávio Bortoluzo De Lorenzo | D30: A - Sim | F30: otavio.bortoluzo@gmail.com | H30: B - Masculino | I30: D - Superior (ou 3º grau) | J30: A - Sim, trabalho | K30: B - Branca | L30: D - Espírita | M30: Campinas | N30: Jardim Guanabara | P30: C - Não tenho | Q30: C - Não tenho | R30: B - Boa | S30: C - Não | T30: B - Sim, às vezes | U30: A - Sim | V30: A - Ruim, não sabem LIBRAS e sou obrigado a oralizar | W30: D - Não, porque não tem Central de Interpretação de Libras na minha cidade | X30: A - Sim | Y30: A - Ruim, não sabem LIBRAS e sou obrigado a oralizar | Z30: A - Sim | AA30: A - Sim | AB30: A - Ruim, não sabe LIBRAS e sou obrigado a oralizar | AC30: B - Não
A31: 18/08/2021 22:17:35 | B31: Sim, aceito participar da pesquisa | C31: Elaine Patricia de Oliveira do Prado | D31: B - Não | E31: 19981898665 | F31: elainecorreaoliveira837@gmail.com | G31: 11/09/1981 | H31: A - Feminino | I31: C - Médio (ou 2º grau) | J31: E - Não, estou desempregado | K31: C - Parda | L31: A - Não tenho religião | M31: Hortolândia | N31: Parque do horto | O31: 13183660 | P31: C - Não tenho | Q31: C - Não tenho | R31: C - Regular | S31: C - Não | T31: B - Sim, às vezes | U31: A - Sim | V31: A - Ruim, não sabem LIBRAS e sou obrigado a oralizar | W31: D - Não, porque não tem Central de Interpretação de Libras na minha cidade | X31: A - Sim | Y31: A - Ruim, não sabem LIBRAS e sou obrigado a oralizar | Z31: B - Não | AC31: B - Não
A32: 19/08/2021 08:43:32 | B32: Sim, aceito participar da pesquisa | C32: Rodrigo Modesto Barros | D32: A - Sim | E32: 19 992844449 | F32: darcisb@yahoo.com.br | G32: 27/12/1989 | H32: B - Masculino | I32: C - Médio (ou 2º grau) | J32: A - Sim, trabalho | K32: B - Branca | L32: B - Católica | M32: Campinas | N32: Jd. Santa Lúcia | O32: 13060476 | P32: C - Não tenho | Q32: C - Não tenho | R32: B - Boa | S32: C - Não | T32: C - Não | U32: B - Não | X32: A - Sim | Y32: B - Ruim, não sabem LIBRAS e preciso escrever português | Z32: B - Não | AC32: B - Não
A33: 19/08/2021 10:24:58 | B33: Sim, aceito participar da pesquisa | C33: Luis Fernando Assi | D33: B - Não | E33: 35991096017 | F33: luisfernandoassi39@gmail.com | G33: 10/05/1983 | H33: B - Masculino | I33: D - Superior (ou 3º grau) | J33: A - Sim, trabalho | K33: C - Parda | L33: C - Evangélica | M33: Poços de Caldas | N33: Chácara alvorada | O33: 37706003 | P33: C - Não tenho | Q33: C - Não tenho | R33: A - Muito boa | S33: C - Não | T33: B - Sim, às vezes | U33: B - Não | X33: A - Sim | Y33: A - Ruim, não sabem LIBRAS e sou obrigado a oralizar | Z33: B - Não | AC33: B - Não
A34: 19/08/2021 12:37:33 | B34: Sim, aceito participar da pesquisa | C34: Viviane Oliveira da Silva | D34: A - Sim | E34: 1998171-3841 | F34: vs8950533@gmail.com | G34: 02/03/1991 | H34: A - Feminino | I34: D - Superior (ou 3º grau) | J34: E - Não, estou desempregado | K34: C - Parda | L34: C - Evangélica | M34: Valinhos | N34: Jd do Lago | O34: 13277-511 | P34: C - Não tenho | Q34: C - Não tenho | R34: C - Regular | S34: C - Não | T34: C - Não | U34: A - Sim | V34: A - Ruim, não sabem LIBRAS e sou obrigado a oralizar | W34: D - Não, porque não tem Central de Interpretação de Libras na minha cidade | X34: B - Não | Z34: A - Sim | AA34: A - Sim | AB34: D - Boa, tem intérprete que me ajuda | AC34: B - Não
A35: 19/08/2021 18:51:54 | B35: Sim, aceito participar da pesquisa | C35: Anderson Caiton de Miranda. | D35: A - Sim | E35: 19994162462 | F35: andy_cm_1975@hotmail.com | G35: 24/07/1975 | H35: B - Masculino | I35: E - Pós-graduação (especialização, mestrado, doutorado) | J35: B - Não trabalho e recebo benefício BPC/INSS | K35: B - Branca | L35: D - Espírita | M35: Sumarê SP | N35: Vila yolinda costa e Silva | O35: 13172200 | P35: C - Não tenho | Q35: C - Não tenho | R35: B - Boa | S35: B - Sim, às vezes | T35: B - Sim, às vezes | U35: A - Sim | V35: E - Boa, porque familiar me ajuda | W35: D - Não, porque não tem Central de Interpretação de Libras na minha cidade | X35: A - Sim | Y35: D - Boa, tem intérprete que me ajuda | Z35: B - Não | AC35: B - Não
A36: 19/08/2021 19:18:11 | B36: Sim, aceito participar da pesquisa | C36: Emerson Gabriel dos Santos Afonso | D36: A - Sim | E36: 19982947507 | F36: claudiapereiragabipri@gmail.com | G36: 14/06/2005 | H36: B - Masculino | I36: B - Fundamental (ou 1º grau) | J36: D - Não, porque sou estudante | K36: C - Parda | L36: C - Evangélica | M36: Hortolândia | N36: Jardim Amanda 2 | O36: 13188142 | P36: C - Não tenho | Q36: C - Não tenho | R36: C - Regular | S36: C - Não | T36: C - Não | U36: B - Não | X36: A - Sim | Y36: C - Ruim, não consigo comunicação | Z36: B - Não | AC36: A - Sim | AD36: A - Sim | AE36: E - Boa, porque familiar me ajuda
A37: 19/08/2021 21:59:47 | B37: Sim, aceito participar da pesquisa | C37: José Pereira dos Santos | D37: A - Sim | E37: 19-983115102 | F37: José.p73@icloud.com | G37: 21/02/1973 | H37: B - Masculino | I37: C - Médio (ou 2º grau) | J37: A - Sim, trabalho | K37: B - Branca | L37: B - Católica | M37: Hortolândia-SP | N37: Santa Esmeralda | O37: 13186533 | P37: C - Não tenho | Q37: C - Não tenho | R37: A - Muito boa | S37: C - Não | T37: C - Não | U37: B - Não | X37: B - Não | Z37: B - Não | AC37: B - Não
A38: 21/08/2021 09:01:49 | B38: Sim, aceito participar da pesquisa | C38: Renato Alberto Capodalio de Souza | D38: A - Sim | E38: 19988521989 | F38: renatocapodalio0@gmail.com | G38: 25/02/1989 | H38: B - Masculino | I38: E - Pós-graduação (especialização, mestrado, doutorado) | J38: A - Sim, trabalho | K38: B - Branca | L38: C - Evangélica | M38: Campinas | N38: Jardim Santa Genebra | O38: 13080080 | P38: C - Não tenho | Q38: C - Não tenho | R38: C - Regular | S38: C - Não | T38: B - Sim, às vezes | U38: B - Não | X38: A - Sim | Y38: A - Ruim, não sabem LIBRAS e sou obrigado a oralizar | Z38: B - Não | AC38: B - Não
A39: 21/08/2021 12:28:37 | B39: Sim, aceito participar da pesquisa | C39: Augusto E.P.criscione | D39: A - Sim | F39: gucris4@gmail.com | H39: B - Masculino | I39: D - Superior (ou 3º grau) | J39: A - Sim, trabalho | K39: B - Branca | L39: C - Evangélica | M39: Campinas | N39: Parque eucaliptos | O39: 13061 371 | P39: C - Não tenho | Q39: C - Não tenho | R39: B - Boa | S39: C - Não | T39: C - Não | U39: B - Não | X39: A - Sim | Y39: D - Boa, tem intérprete que me ajuda | Z39: A - Sim | AA39: B - Não | AC39: B - Não
A40: 21/08/2021 13:24:39 | D40: A - Sim | E40: 19996755099 | F40: librascampinas@gmail.com | G40: 27/04/2022 | H40: A - Feminino | I40: E - Pós-graduação (especialização, mestrado, doutorado) | J40: A - Sim, trabalho | K40: B - Branca | L40: D - Espírita | M40: Campinas | N40: Jardim Eulina | P40: C - Não tenho | Q40: A - Sim e faço tratamento com remédios | R40: C - Regular | S40: C - Não | T40: C - Não | U40: B - Não | X40: A - Sim | Y40: A - Ruim, não sabem LIBRAS e sou obrigado a oralizar | Z40: B - Não | AC40: B - Não
...

Sheet filtro_revisto
A1: V001 | B1: VALIDA | C1: TCLE | D1: publico_alvo | E1: idade | F1: RMC | G1: Cidade | H1: usa_SUS | I1: Comunica_SUS | J1: rede_privada | K1: Comunica_rede_privada
A2: 17/08/2021 23:05:23 | B2: FALSE | C2: Sim, aceito participar da pesquisa | D2: Não | E2: 35 | F2: FALSE | G2: IRACEMAPOLIS | H2: Sim | I2: Boa, porque familiar me ajuda | J2: Sim | K2: Boa, porque familiar me ajuda
A3: 18/08/2021 19:21:16 | B3: FALSE | C3: Sim, aceito participar da pesquisa | D3: Não | E3: 18 | F3: FALSE | G3: CAPIVARI | H3: Sim | I3: Boa, porque familiar me ajuda | J3: Não | K3: NA
A4: 19/08/2021 10:24:58 | B4: FALSE | C4: Sim, aceito participar da pesquisa | D4: Não | E4: 38 | F4: FALSE | G4: POCOS DE CALDAS | H4: Não | I4: NA | J4: Sim | K4: Ruim, não sabem LIBRAS e sou obrigado a oralizar
A5: 21/08/2021 15:22:00 | B5: FALSE | C5: Sim, aceito participar da pesquisa | D5: Não | E5: 37 | F5: FALSE | G5: SAO JOSE DO RIO PARDO | H5: Não | I5: NA | J5: Sim | K5: Boa, porque familiar me ajuda
A6: 27/08/2021 13:25:27 | B6: FALSE | C6: Sim, aceito participar da pesquisa | D6: Não | E6: 64 | F6: FALSE | G6: JUNDIAI | H6: Não | I6: NA | J6: Sim | K6: NA
A7: 03/09/2021 20:04:07 | B7: FALSE | C7: Sim, aceito participar da pesquisa | D7: Não | E7: 31 | F7: FALSE | G7: CACHOEIRA DE MINAS MG | H7: Não | I7: NA | J7: Não | K7: NA
A8: 28/09/2021 12:35:29 | B8: FALSE | C8: Sim, aceito participar da pesquisa | D8: Não | E8: 32 | F8: FALSE | G8: LIMEIRA | H8: Sim | I8: Ruim, não sabem LIBRAS e sou obrigado a oralizar | J8: Sim | K8: Ruim, não sabem LIBRAS e sou obrigado a oralizar
A9: 06/10/2021 19:52:44 | B9: FALSE | C9: Sim, aceito participar da pesquisa | D9: Não | E9: 28 | F9: FALSE | G9: MEDINA MG | H9: Sim | I9: Ruim, não sabem LIBRAS e preciso escrever português | J9: Sim | K9: Ruim, não sabem LIBRAS e preciso escrever português
A10: 07/10/2021 15:16:22 | B10: FALSE | C10: Sim, aceito participar da pesquisa | D10: Não | E10: 34 | F10: FALSE | G10: OSASCO | H10: Sim | I10: Boa, porque familiar me ajuda | J10: Não | K10: NA
A11: 13/10/2021 21:53:30 | B11: FALSE | C11: Sim, aceito participar da pesquisa | D11: Não | E11: 35 | F11: FALSE | G11: SANTANA | H11: Sim | I11: Ruim, não sabem LIBRAS e preciso escrever português | J11: Não | K11: NA
A12: 13/10/2021 22:53:58 | B12: FALSE | C12: Sim, aceito participar da pesquisa | D12: Não | E12: 36 | F12: FALSE | G12: BRASILIA, MORAVA CAMPINAS | H12: Sim | I12: Ruim, não sabem LIBRAS e preciso escrever português | J12: Sim | K12: Ruim, não sabem LIBRAS e preciso escrever português
A13: 18/08/2021 07:39:08 | B13: FALSE | C13: NA | D13: Não | E13: 68 | F13: TRUE | G13: CAMPINAS | H13: Sim | I13: Ruim, não consigo comunicação | J13: Não | K13: NA
... A33: 06/10/2021 19:53:23 | B33: FALSE | C33: Sim, aceito participar da pesquisa | D33: Sim | E33: 12 | F33: TRUE | G33: CAMPINAS | H33: Sim | I33: Boa, tem intérprete que me ajuda | J33: Sim | K33: Boa, tem intérprete que me ajuda
A34: 26/08/2021 09:26:15 | B34: FALSE | C34: NA | D34: NA | E34: NA | F34: FALSE | G34: NA | H34: NA | I34: NA | J34: NA | K34: NA
A35: 08/10/2021 20:34:59 | B35: FALSE | C35: NA | D35: NA | E35: NA | F35: FALSE | G35: NA | H35: NA | I35: Boa, tem intérprete que me ajuda | J35: NA | K35: NA
A36: 06/10/2021 20:49:53 | B36: FALSE | C36: Sim, aceito participar da pesquisa | D36: NA | E36: NA | F36: TRUE | G36: SUMARE | H36: Sim | I36: Ruim, não consigo comunicação | J36: Sim | K36: Ruim, não consigo comunicação
A37: 06/10/2021 22:23:42 | B37: FALSE | C37: Sim, aceito participar da pesquisa | D37: NA | E37: NA | F37: TRUE | G37: AMPARO | H37: Sim | I37: Boa, porque familiar me ajuda | J37: Sim | K37: Boa, porque familiar me ajuda
A38: 07/10/2021 16:18:40 | B38: FALSE | C38: NA | D38: NA | E38: 30 | F38: TRUE | G38: CAMPINAS | H38: Sim | I38: NA | J38: Sim | K38: NA
A39: 13/10/2021 19:10:17 | B39: FALSE | C39: NA | D39: NA | E39: NA | F39: TRUE | G39: PAULINIA | H39: Não | I39: NA | J39: Sim | K39: Ruim, não sabem LIBRAS e sou obrigado a oralizar
A40: 17/08/2021 12:17:51 | B40: TRUE | C40: Sim, aceito participar da pesquisa | D40: Sim | E40: 19 | F40: FALSE | G40: NA | H40: Sim | I40: Boa, o profissional de saúde sabe LIBRAS | J40: Sim | K40: Boa, tem intérprete que me ajuda
A41: 26/09/2021 17:43:15 | B41: TRUE | C41: NA | D41: Sim | E41: NA | F41: FALSE | G41: NA | H41: Não | I41: NA | J41: Não | K41: NA
A42: 16/08/2021 20:23:13 | B42: TRUE | C42: Sim, aceito participar da pesquisa | D42: Sim | E42: 32 | F42: TRUE | G42: SUMARE | H42: Sim | I42: Boa, porque familiar me ajuda | J42: Sim | K42: Boa, porque familiar me ajuda
A43: 17/08/2021 12:37:32 | B43: TRUE | C43: Sim, aceito participar da pesquisa | D43: Sim | E43: 42 | F43: TRUE | G43: CAMPINAS | H43: Sim | I43: Ruim, não consigo comunicação | J43: Sim | K43: Ruim, não consigo comunicação
A44: 17/08/2021 16:53:13 | B44: TRUE | C44: Sim, aceito participar da pesquisa | D44: Sim | E44: 50 | F44: TRUE | G44: HORTOLANDIA | H44: Sim | I44: Ruim, não sabem LIBRAS e sou obrigado a oralizar | J44: Sim | K44: Ruim, não sabem LIBRAS e sou obrigado a oralizar
A45: 17/08/2021 17:35:36 | B45: TRUE | C45: Sim, aceito participar da pesquisa | D45: Sim | E45: 34 | F45: TRUE | G45: CAMPINAS | H45: Sim | I45: Ruim, não sabem LIBRAS e sou obrigado a oralizar | J45: Não | K45: NA
A46: 17/08/2021 20:13:30 | B46: TRUE | C46: Sim, aceito participar da pesquisa | D46: Sim | E46: 31 | F46: TRUE | G46: CAMPINAS | H46: Não | I46: NA | J46: Sim | K46: Ruim, não sabem LIBRAS e sou obrigado a oralizar
A47: 17/08/2021 20:29:52 | B47: TRUE | C47: Sim, aceito participar da pesquisa | D47: Sim | E47: 29 | F47: TRUE | G47: SUMARE | H47: Sim | I47: Ruim, não consigo comunicação | J47: Não | K47: NA
A48: 17/08/2021 20:56:37 | B48: TRUE | C48: Sim, aceito participar da pesquisa | D48: Sim | E48: 30 | F48: TRUE | G48: CAMPINAS | H48: Não | I48: NA | J48: Sim | K48: Boa, o profissional de saúde sabe LIBRAS
A49: 17/08/2021 21:24:13 | B49: TRUE | C49: Sim, aceito participar da pesquisa | D49: Sim | E49: 60 | F49: TRUE | G49: PAULINIA | H49: Não | I49: NA | J49: Sim | K49: Boa, porque familiar me ajuda
A50: 17/08/2021 23:21:46 | B50: TRUE | C50: Sim, aceito participar da pesquisa | D50: Sim | E50: 32 | F50: TRUE | G50: SANTA BARBARA D OESTE | H50: Não | I50: NA | J50: Não | K50: NA
A51: 17/08/2021 23:35:59 | B51: TRUE | C51: Sim, aceito participar da pesquisa | D51: Sim | E51: 36 | F51: TRUE | G51: CAMPINAS | H51: Não | I51: NA | J51: Sim | K51: Ruim, não sabem LIBRAS e preciso escrever português
A52: 18/08/2021 07:23:44 | B52: TRUE | C52: Sim, aceito participar da pesquisa | D52: Sim | E52: 50 | F52: TRUE | G52: CAMPINAS | H52: Sim | I52: Ruim, não sabem LIBRAS e preciso escrever português | J52: Não | K52: NA
A53: 18/08/2021 09:34:22 | B53: TRUE | C53: Sim, aceito participar da pesquisa | D53: Sim | E53: 54 | F53: TRUE | G53: CAMPINAS | H53: Sim | I53: Ruim, não sabem LIBRAS e sou obrigado a oralizar | J53: Sim | K53: Ruim, não sabem LIBRAS e sou obrigado a oralizar
... A262: 27/09/2021 14:16:00 | B262: TRUE | C262: Sim, aceito participar da pesquisa | D262: NA | E262: 46 | F262: TRUE | G262: CAMPINAS | H262: Não | I262: NA | J262: Sim | K262: Boa, tem intérprete que me ajuda
